
[07/17/2017 02:50:05] INFO [OmniDB_app.views.login:103] User "admin" logged in.
[07/17/2017 02:50:05] ERROR [django.request:135] Internal Server Error: /get_database_list/
Traceback (most recent call last):
  File "/usr/local/lib/python3.5/dist-packages/django/core/handlers/exception.py", line 41, in inner
    response = get_response(request)
  File "/usr/local/lib/python3.5/dist-packages/django/core/handlers/base.py", line 187, in _get_response
    response = self.process_exception_by_middleware(e, request)
  File "/usr/local/lib/python3.5/dist-packages/django/core/handlers/base.py", line 185, in _get_response
    response = wrapped_callback(request, *callback_args, **callback_kwargs)
  File "/home/israel/Repositórios/OmniDB/OmniDB/OmniDB_app/views/workspace.py", line 155, in get_database_list
    v_options = v_options + '<option data-image="/static/OmniDB_app/images/{0}_medium.png\" value="{1}" data-description="{2}">{3}{4}</option>'.format(v_database.v_db_type,v_index,v_database.PrintDatabaseDetails(),v_alias,v_database.PrintDatabaseInfo())
  File "/usr/local/lib/python3.5/dist-packages/OmniDatabase/__init__.py", line 171, in PrintDatabaseInfo
    return self.v_user + "@" + self.v_service + " - " + self.v_schema
TypeError: Can't convert 'int' object to str implicitly
[07/17/2017 02:50:05] ERROR [django.server:124] "POST /get_database_list/ HTTP/1.1" 500 17848
[07/17/2017 02:50:18] ERROR [django.request:135] Internal Server Error: /get_database_list/
Traceback (most recent call last):
  File "/usr/local/lib/python3.5/dist-packages/django/core/handlers/exception.py", line 41, in inner
    response = get_response(request)
  File "/usr/local/lib/python3.5/dist-packages/django/core/handlers/base.py", line 187, in _get_response
    response = self.process_exception_by_middleware(e, request)
  File "/usr/local/lib/python3.5/dist-packages/django/core/handlers/base.py", line 185, in _get_response
    response = wrapped_callback(request, *callback_args, **callback_kwargs)
  File "/home/israel/Repositórios/OmniDB/OmniDB/OmniDB_app/views/workspace.py", line 155, in get_database_list
    v_options = v_options + '<option data-image="/static/OmniDB_app/images/{0}_medium.png\" value="{1}" data-description="{2}">{3}{4}</option>'.format(v_database.v_db_type,v_index,v_database.PrintDatabaseDetails(),v_alias,v_database.PrintDatabaseInfo())
  File "/usr/local/lib/python3.5/dist-packages/OmniDatabase/__init__.py", line 171, in PrintDatabaseInfo
    return self.v_user + "@" + self.v_service + " - " + self.v_schema
TypeError: Can't convert 'int' object to str implicitly
[07/17/2017 02:50:18] ERROR [django.server:124] "POST /get_database_list/ HTTP/1.1" 500 17848
[07/17/2017 02:50:33] ERROR [django.request:135] Internal Server Error: /get_database_list/
Traceback (most recent call last):
  File "/usr/local/lib/python3.5/dist-packages/django/core/handlers/exception.py", line 41, in inner
    response = get_response(request)
  File "/usr/local/lib/python3.5/dist-packages/django/core/handlers/base.py", line 187, in _get_response
    response = self.process_exception_by_middleware(e, request)
  File "/usr/local/lib/python3.5/dist-packages/django/core/handlers/base.py", line 185, in _get_response
    response = wrapped_callback(request, *callback_args, **callback_kwargs)
  File "/home/israel/Repositórios/OmniDB/OmniDB/OmniDB_app/views/workspace.py", line 155, in get_database_list
    v_options = v_options + '<option data-image="/static/OmniDB_app/images/{0}_medium.png\" value="{1}" data-description="{2}">{3}{4}</option>'.format(v_database.v_db_type,v_index,v_database.PrintDatabaseDetails(),v_alias,v_database.PrintDatabaseInfo())
  File "/usr/local/lib/python3.5/dist-packages/OmniDatabase/__init__.py", line 171, in PrintDatabaseInfo
    return self.v_user + "@" + self.v_service + " - " + self.v_schema
TypeError: Can't convert 'int' object to str implicitly
[07/17/2017 02:50:33] ERROR [django.server:124] "POST /get_database_list/ HTTP/1.1" 500 17848
[07/17/2017 02:51:48] ERROR [django.request:135] Internal Server Error: /get_database_list/
Traceback (most recent call last):
  File "/usr/local/lib/python3.5/dist-packages/django/core/handlers/exception.py", line 41, in inner
    response = get_response(request)
  File "/usr/local/lib/python3.5/dist-packages/django/core/handlers/base.py", line 187, in _get_response
    response = self.process_exception_by_middleware(e, request)
  File "/usr/local/lib/python3.5/dist-packages/django/core/handlers/base.py", line 185, in _get_response
    response = wrapped_callback(request, *callback_args, **callback_kwargs)
  File "/home/israel/Repositórios/OmniDB/OmniDB/OmniDB_app/views/workspace.py", line 155, in get_database_list
    v_options = v_options + '<option data-image="/static/OmniDB_app/images/{0}_medium.png\" value="{1}" data-description="{2}">{3}{4}</option>'.format(v_database.v_db_type,v_index,v_database.PrintDatabaseDetails(),v_alias,v_database.PrintDatabaseInfo())
  File "/usr/local/lib/python3.5/dist-packages/OmniDatabase/__init__.py", line 171, in PrintDatabaseInfo
    return self.v_user + "@" + self.v_service + " - " + self.v_schema
TypeError: Can't convert 'int' object to str implicitly
[07/17/2017 02:51:48] ERROR [django.server:124] "POST /get_database_list/ HTTP/1.1" 500 17848
[07/17/2017 02:56:04] ERROR [django.request:135] Internal Server Error: /get_database_list/
Traceback (most recent call last):
  File "/usr/local/lib/python3.5/dist-packages/django/core/handlers/exception.py", line 41, in inner
    response = get_response(request)
  File "/usr/local/lib/python3.5/dist-packages/django/core/handlers/base.py", line 187, in _get_response
    response = self.process_exception_by_middleware(e, request)
  File "/usr/local/lib/python3.5/dist-packages/django/core/handlers/base.py", line 185, in _get_response
    response = wrapped_callback(request, *callback_args, **callback_kwargs)
  File "/home/israel/Repositórios/OmniDB/OmniDB/OmniDB_app/views/workspace.py", line 155, in get_database_list
    v_options = v_options + '<option data-image="/static/OmniDB_app/images/{0}_medium.png\" value="{1}" data-description="{2}">{3}{4}</option>'.format(v_database.v_db_type,v_index,v_database.PrintDatabaseDetails(),v_alias,v_database.PrintDatabaseInfo())
  File "/usr/local/lib/python3.5/dist-packages/OmniDatabase/__init__.py", line 171, in PrintDatabaseInfo
    return self.v_user + "@" + self.v_service + " - " + self.v_schema
TypeError: Can't convert 'int' object to str implicitly
[07/17/2017 02:56:04] ERROR [django.server:124] "POST /get_database_list/ HTTP/1.1" 500 17848
[07/17/2017 02:56:44] ERROR [django.request:135] Internal Server Error: /get_database_list/
Traceback (most recent call last):
  File "/usr/local/lib/python3.5/dist-packages/django/core/handlers/exception.py", line 41, in inner
    response = get_response(request)
  File "/usr/local/lib/python3.5/dist-packages/django/core/handlers/base.py", line 187, in _get_response
    response = self.process_exception_by_middleware(e, request)
  File "/usr/local/lib/python3.5/dist-packages/django/core/handlers/base.py", line 185, in _get_response
    response = wrapped_callback(request, *callback_args, **callback_kwargs)
  File "/home/israel/Repositórios/OmniDB/OmniDB/OmniDB_app/views/workspace.py", line 155, in get_database_list
    v_options = v_options + '<option data-image="/static/OmniDB_app/images/{0}_medium.png\" value="{1}" data-description="{2}">{3}{4}</option>'.format(v_database.v_db_type,v_index,v_database.PrintDatabaseDetails(),v_alias,v_database.PrintDatabaseInfo())
  File "/usr/local/lib/python3.5/dist-packages/OmniDatabase/__init__.py", line 171, in PrintDatabaseInfo
    return self.v_user + "@" + self.v_service + " - " + self.v_schema
TypeError: Can't convert 'int' object to str implicitly
[07/17/2017 02:56:44] ERROR [django.server:124] "POST /get_database_list/ HTTP/1.1" 500 17848
[07/17/2017 03:08:11] INFO [OmniDB_app.views.login:37] User "admin" logged out.
[07/17/2017 03:08:15] INFO [OmniDB_app.views.login:103] User "admin" logged in.
[07/17/2017 03:29:00] ERROR [django.request:135] Internal Server Error: /workspace/
Traceback (most recent call last):
  File "/usr/local/lib/python3.5/dist-packages/django/core/handlers/exception.py", line 41, in inner
    response = get_response(request)
  File "/usr/local/lib/python3.5/dist-packages/django/core/handlers/base.py", line 187, in _get_response
    response = self.process_exception_by_middleware(e, request)
  File "/usr/local/lib/python3.5/dist-packages/django/core/handlers/base.py", line 185, in _get_response
    response = wrapped_callback(request, *callback_args, **callback_kwargs)
  File "/home/israel/Repositórios/OmniDB/OmniDB/OmniDB_app/views/workspace.py", line 49, in index
    template = loader.get_template('OmniDB_app/workspace.html')
  File "/usr/local/lib/python3.5/dist-packages/django/template/loader.py", line 21, in get_template
    return engine.get_template(template_name)
  File "/usr/local/lib/python3.5/dist-packages/django/template/backends/django.py", line 39, in get_template
    return Template(self.engine.get_template(template_name), self)
  File "/usr/local/lib/python3.5/dist-packages/django/template/engine.py", line 162, in get_template
    template, origin = self.find_template(template_name)
  File "/usr/local/lib/python3.5/dist-packages/django/template/engine.py", line 136, in find_template
    name, template_dirs=dirs, skip=skip,
  File "/usr/local/lib/python3.5/dist-packages/django/template/loaders/base.py", line 44, in get_template
    contents, origin, origin.template_name, self.engine,
  File "/usr/local/lib/python3.5/dist-packages/django/template/base.py", line 191, in __init__
    self.nodelist = self.compile_nodelist()
  File "/usr/local/lib/python3.5/dist-packages/django/template/base.py", line 230, in compile_nodelist
    return parser.parse()
  File "/usr/local/lib/python3.5/dist-packages/django/template/base.py", line 515, in parse
    raise self.error(token, e)
  File "/usr/local/lib/python3.5/dist-packages/django/template/base.py", line 513, in parse
    compiled_result = compile_func(self, token)
  File "/usr/local/lib/python3.5/dist-packages/django/template/loader_tags.py", line 312, in do_extends
    nodelist = parser.parse()
  File "/usr/local/lib/python3.5/dist-packages/django/template/base.py", line 515, in parse
    raise self.error(token, e)
  File "/usr/local/lib/python3.5/dist-packages/django/template/base.py", line 513, in parse
    compiled_result = compile_func(self, token)
  File "/usr/local/lib/python3.5/dist-packages/django/template/loader_tags.py", line 255, in do_block
    nodelist = parser.parse(('endblock',))
  File "/usr/local/lib/python3.5/dist-packages/django/template/base.py", line 482, in parse
    raise self.error(token, 'Empty variable tag on line %d' % token.lineno)
django.template.exceptions.TemplateSyntaxError: Empty variable tag on line 223
[07/17/2017 03:29:00] ERROR [django.server:124] "GET /workspace/ HTTP/1.1" 500 155592
[07/17/2017 03:29:06] ERROR [django.request:135] Internal Server Error: /workspace/
Traceback (most recent call last):
  File "/usr/local/lib/python3.5/dist-packages/django/core/handlers/exception.py", line 41, in inner
    response = get_response(request)
  File "/usr/local/lib/python3.5/dist-packages/django/core/handlers/base.py", line 187, in _get_response
    response = self.process_exception_by_middleware(e, request)
  File "/usr/local/lib/python3.5/dist-packages/django/core/handlers/base.py", line 185, in _get_response
    response = wrapped_callback(request, *callback_args, **callback_kwargs)
  File "/home/israel/Repositórios/OmniDB/OmniDB/OmniDB_app/views/workspace.py", line 49, in index
    template = loader.get_template('OmniDB_app/workspace.html')
  File "/usr/local/lib/python3.5/dist-packages/django/template/loader.py", line 21, in get_template
    return engine.get_template(template_name)
  File "/usr/local/lib/python3.5/dist-packages/django/template/backends/django.py", line 39, in get_template
    return Template(self.engine.get_template(template_name), self)
  File "/usr/local/lib/python3.5/dist-packages/django/template/engine.py", line 162, in get_template
    template, origin = self.find_template(template_name)
  File "/usr/local/lib/python3.5/dist-packages/django/template/engine.py", line 136, in find_template
    name, template_dirs=dirs, skip=skip,
  File "/usr/local/lib/python3.5/dist-packages/django/template/loaders/base.py", line 44, in get_template
    contents, origin, origin.template_name, self.engine,
  File "/usr/local/lib/python3.5/dist-packages/django/template/base.py", line 191, in __init__
    self.nodelist = self.compile_nodelist()
  File "/usr/local/lib/python3.5/dist-packages/django/template/base.py", line 230, in compile_nodelist
    return parser.parse()
  File "/usr/local/lib/python3.5/dist-packages/django/template/base.py", line 515, in parse
    raise self.error(token, e)
  File "/usr/local/lib/python3.5/dist-packages/django/template/base.py", line 513, in parse
    compiled_result = compile_func(self, token)
  File "/usr/local/lib/python3.5/dist-packages/django/template/loader_tags.py", line 312, in do_extends
    nodelist = parser.parse()
  File "/usr/local/lib/python3.5/dist-packages/django/template/base.py", line 515, in parse
    raise self.error(token, e)
  File "/usr/local/lib/python3.5/dist-packages/django/template/base.py", line 513, in parse
    compiled_result = compile_func(self, token)
  File "/usr/local/lib/python3.5/dist-packages/django/template/loader_tags.py", line 255, in do_block
    nodelist = parser.parse(('endblock',))
  File "/usr/local/lib/python3.5/dist-packages/django/template/base.py", line 482, in parse
    raise self.error(token, 'Empty variable tag on line %d' % token.lineno)
django.template.exceptions.TemplateSyntaxError: Empty variable tag on line 223
[07/17/2017 03:29:07] ERROR [django.server:124] "GET /workspace/ HTTP/1.1" 500 155592
[07/17/2017 03:29:19] ERROR [django.request:135] Internal Server Error: /workspace/
Traceback (most recent call last):
  File "/usr/local/lib/python3.5/dist-packages/django/core/handlers/exception.py", line 41, in inner
    response = get_response(request)
  File "/usr/local/lib/python3.5/dist-packages/django/core/handlers/base.py", line 187, in _get_response
    response = self.process_exception_by_middleware(e, request)
  File "/usr/local/lib/python3.5/dist-packages/django/core/handlers/base.py", line 185, in _get_response
    response = wrapped_callback(request, *callback_args, **callback_kwargs)
  File "/home/israel/Repositórios/OmniDB/OmniDB/OmniDB_app/views/workspace.py", line 49, in index
    template = loader.get_template('OmniDB_app/workspace.html')
  File "/usr/local/lib/python3.5/dist-packages/django/template/loader.py", line 21, in get_template
    return engine.get_template(template_name)
  File "/usr/local/lib/python3.5/dist-packages/django/template/backends/django.py", line 39, in get_template
    return Template(self.engine.get_template(template_name), self)
  File "/usr/local/lib/python3.5/dist-packages/django/template/engine.py", line 162, in get_template
    template, origin = self.find_template(template_name)
  File "/usr/local/lib/python3.5/dist-packages/django/template/engine.py", line 136, in find_template
    name, template_dirs=dirs, skip=skip,
  File "/usr/local/lib/python3.5/dist-packages/django/template/loaders/base.py", line 44, in get_template
    contents, origin, origin.template_name, self.engine,
  File "/usr/local/lib/python3.5/dist-packages/django/template/base.py", line 191, in __init__
    self.nodelist = self.compile_nodelist()
  File "/usr/local/lib/python3.5/dist-packages/django/template/base.py", line 230, in compile_nodelist
    return parser.parse()
  File "/usr/local/lib/python3.5/dist-packages/django/template/base.py", line 515, in parse
    raise self.error(token, e)
  File "/usr/local/lib/python3.5/dist-packages/django/template/base.py", line 513, in parse
    compiled_result = compile_func(self, token)
  File "/usr/local/lib/python3.5/dist-packages/django/template/loader_tags.py", line 312, in do_extends
    nodelist = parser.parse()
  File "/usr/local/lib/python3.5/dist-packages/django/template/base.py", line 515, in parse
    raise self.error(token, e)
  File "/usr/local/lib/python3.5/dist-packages/django/template/base.py", line 513, in parse
    compiled_result = compile_func(self, token)
  File "/usr/local/lib/python3.5/dist-packages/django/template/loader_tags.py", line 255, in do_block
    nodelist = parser.parse(('endblock',))
  File "/usr/local/lib/python3.5/dist-packages/django/template/base.py", line 482, in parse
    raise self.error(token, 'Empty variable tag on line %d' % token.lineno)
django.template.exceptions.TemplateSyntaxError: Empty variable tag on line 223
[07/17/2017 03:29:19] ERROR [django.server:124] "GET /workspace/ HTTP/1.1" 500 155592
[07/17/2017 03:29:28] INFO [OmniDB_app.views.login:103] User "admin" logged in.
[07/17/2017 03:29:28] ERROR [django.request:135] Internal Server Error: /workspace/
Traceback (most recent call last):
  File "/usr/local/lib/python3.5/dist-packages/django/core/handlers/exception.py", line 41, in inner
    response = get_response(request)
  File "/usr/local/lib/python3.5/dist-packages/django/core/handlers/base.py", line 187, in _get_response
    response = self.process_exception_by_middleware(e, request)
  File "/usr/local/lib/python3.5/dist-packages/django/core/handlers/base.py", line 185, in _get_response
    response = wrapped_callback(request, *callback_args, **callback_kwargs)
  File "/home/israel/Repositórios/OmniDB/OmniDB/OmniDB_app/views/workspace.py", line 49, in index
    template = loader.get_template('OmniDB_app/workspace.html')
  File "/usr/local/lib/python3.5/dist-packages/django/template/loader.py", line 21, in get_template
    return engine.get_template(template_name)
  File "/usr/local/lib/python3.5/dist-packages/django/template/backends/django.py", line 39, in get_template
    return Template(self.engine.get_template(template_name), self)
  File "/usr/local/lib/python3.5/dist-packages/django/template/engine.py", line 162, in get_template
    template, origin = self.find_template(template_name)
  File "/usr/local/lib/python3.5/dist-packages/django/template/engine.py", line 136, in find_template
    name, template_dirs=dirs, skip=skip,
  File "/usr/local/lib/python3.5/dist-packages/django/template/loaders/base.py", line 44, in get_template
    contents, origin, origin.template_name, self.engine,
  File "/usr/local/lib/python3.5/dist-packages/django/template/base.py", line 191, in __init__
    self.nodelist = self.compile_nodelist()
  File "/usr/local/lib/python3.5/dist-packages/django/template/base.py", line 230, in compile_nodelist
    return parser.parse()
  File "/usr/local/lib/python3.5/dist-packages/django/template/base.py", line 515, in parse
    raise self.error(token, e)
  File "/usr/local/lib/python3.5/dist-packages/django/template/base.py", line 513, in parse
    compiled_result = compile_func(self, token)
  File "/usr/local/lib/python3.5/dist-packages/django/template/loader_tags.py", line 312, in do_extends
    nodelist = parser.parse()
  File "/usr/local/lib/python3.5/dist-packages/django/template/base.py", line 515, in parse
    raise self.error(token, e)
  File "/usr/local/lib/python3.5/dist-packages/django/template/base.py", line 513, in parse
    compiled_result = compile_func(self, token)
  File "/usr/local/lib/python3.5/dist-packages/django/template/loader_tags.py", line 255, in do_block
    nodelist = parser.parse(('endblock',))
  File "/usr/local/lib/python3.5/dist-packages/django/template/base.py", line 482, in parse
    raise self.error(token, 'Empty variable tag on line %d' % token.lineno)
django.template.exceptions.TemplateSyntaxError: Empty variable tag on line 223
[07/17/2017 03:29:29] ERROR [django.server:124] "GET /workspace/ HTTP/1.1" 500 155445
[07/17/2017 03:54:49] INFO [OmniDB_app.views.login:37] User "admin" logged out.
[07/17/2017 03:54:52] INFO [OmniDB_app.views.login:103] User "admin" logged in.
[07/17/2017 04:00:32] INFO [OmniDB_app.views.login:37] User "admin" logged out.
[07/17/2017 16:17:27] ERROR [django.request:135] Internal Server Error: /sign_in/
Traceback (most recent call last):
  File "/home/israel/.local/lib/python3.5/site-packages/django/core/handlers/exception.py", line 41, in inner
    response = get_response(request)
  File "/home/israel/.local/lib/python3.5/site-packages/django/core/handlers/base.py", line 187, in _get_response
    response = self.process_exception_by_middleware(e, request)
  File "/home/israel/.local/lib/python3.5/site-packages/django/core/handlers/base.py", line 185, in _get_response
    response = wrapped_callback(request, *callback_args, **callback_kwargs)
  File "/home/israel/Repositórios/OmniDB/OmniDB/OmniDB_app/views/login.py", line 75, in sign_in
    True
TypeError: InstantiateDatabase() takes from 6 to 8 positional arguments but 9 were given
[07/17/2017 16:17:27] ERROR [django.server:124] "POST /sign_in/ HTTP/1.1" 500 18175
[07/17/2017 16:17:32] ERROR [django.request:135] Internal Server Error: /sign_in/
Traceback (most recent call last):
  File "/home/israel/.local/lib/python3.5/site-packages/django/core/handlers/exception.py", line 41, in inner
    response = get_response(request)
  File "/home/israel/.local/lib/python3.5/site-packages/django/core/handlers/base.py", line 187, in _get_response
    response = self.process_exception_by_middleware(e, request)
  File "/home/israel/.local/lib/python3.5/site-packages/django/core/handlers/base.py", line 185, in _get_response
    response = wrapped_callback(request, *callback_args, **callback_kwargs)
  File "/home/israel/Repositórios/OmniDB/OmniDB/OmniDB_app/views/login.py", line 75, in sign_in
    True
TypeError: InstantiateDatabase() takes from 6 to 8 positional arguments but 9 were given
[07/17/2017 16:17:32] ERROR [django.server:124] "POST /sign_in/ HTTP/1.1" 500 18175
[07/17/2017 16:18:42] INFO [OmniDB_app.views.login:103] User "admin" logged in.
[07/17/2017 16:29:06] INFO [OmniDB_app.QueryServer:234] *** SQL Command ***
USER: admin,
START: 2017-07-17 16:29:06.521611,
END: 2017-07-17 16:29:06.807973,
DURATION: 0.286362 seconds,
MODE: Query all rows,
STATUS: success,
COMMAND: select * from psproj.tarefas tar
[07/17/2017 16:29:59] INFO [OmniDB_app.QueryServer:234] *** SQL Command ***
USER: admin,
START: 2017-07-17 16:29:59.370302,
END: 2017-07-17 16:29:59.401491,
DURATION: 0.031189 seconds,
MODE: Query all rows,
STATUS: success,
COMMAND: select * from psproj.projetos
[07/17/2017 16:30:05] INFO [OmniDB_app.QueryServer:234] *** SQL Command ***
USER: admin,
START: 2017-07-17 16:30:05.097193,
END: 2017-07-17 16:30:05.125340,
DURATION: 0.028147 seconds,
MODE: Query 10 rows,
STATUS: success,
COMMAND: select * from psproj.tarefas
[07/17/2017 16:30:08] INFO [OmniDB_app.QueryServer:234] *** SQL Command ***
USER: admin,
START: 2017-07-17 16:30:07.923475,
END: 2017-07-17 16:30:08.210504,
DURATION: 0.287029 seconds,
MODE: Query all rows,
STATUS: success,
COMMAND: select * from psproj.tarefas
[07/17/2017 16:32:42] INFO [OmniDB_app.QueryServer:234] *** SQL Command ***
USER: admin,
START: 2017-07-17 16:32:42.804487,
END: 2017-07-17 16:32:42.834036,
DURATION: 0.029549 seconds,
MODE: Query 10 rows,
STATUS: success,
COMMAND: select * from psproj.tarefas
[07/17/2017 16:32:46] INFO [OmniDB_app.QueryServer:234] *** SQL Command ***
USER: admin,
START: 2017-07-17 16:32:46.459636,
END: 2017-07-17 16:32:46.737928,
DURATION: 0.278292 seconds,
MODE: Query all rows,
STATUS: success,
COMMAND: select * from psproj.tarefas
[07/17/2017 16:33:09] INFO [OmniDB_app.QueryServer:234] *** SQL Command ***
USER: admin,
START: 2017-07-17 16:33:08.972723,
END: 2017-07-17 16:33:09.256339,
DURATION: 0.283616 seconds,
MODE: Query all rows,
STATUS: success,
COMMAND: select * from psproj.tarefas
[07/17/2017 16:34:05] INFO [OmniDB_app.QueryServer:234] *** SQL Command ***
USER: admin,
START: 2017-07-17 16:34:04.831230,
END: 2017-07-17 16:34:05.142921,
DURATION: 0.311691 seconds,
MODE: Query all rows,
STATUS: success,
COMMAND: select * from psproj.tarefas 
[07/17/2017 16:35:54] INFO [OmniDB_app.QueryServer:234] *** SQL Command ***
USER: admin,
START: 2017-07-17 16:35:54.293302,
END: 2017-07-17 16:35:54.576784,
DURATION: 0.283482 seconds,
MODE: Query all rows,
STATUS: success,
COMMAND: select * from psproj.tarefas
[07/17/2017 16:36:45] INFO [OmniDB_app.QueryServer:234] *** SQL Command ***
USER: admin,
START: 2017-07-17 16:36:44.841366,
END: 2017-07-17 16:36:45.124432,
DURATION: 0.283066 seconds,
MODE: Query all rows,
STATUS: success,
COMMAND: select * from psproj.tarefas
[07/17/2017 16:37:30] INFO [OmniDB_app.QueryServer:234] *** SQL Command ***
USER: admin,
START: 2017-07-17 16:37:30.343773,
END: 2017-07-17 16:37:30.631311,
DURATION: 0.287538 seconds,
MODE: Query all rows,
STATUS: success,
COMMAND: select * from psproj.tarefas
[07/17/2017 16:56:58] INFO [OmniDB_app.QueryServer:234] *** SQL Command ***
USER: admin,
START: 2017-07-17 16:56:57.974580,
END: 2017-07-17 16:56:58.258569,
DURATION: 0.283989 seconds,
MODE: Query all rows,
STATUS: success,
COMMAND: select * from psproj.tarefas
[07/17/2017 17:00:56] INFO [OmniDB_app.QueryServer:234] *** SQL Command ***
USER: admin,
START: 2017-07-17 17:00:56.408658,
END: 2017-07-17 17:00:56.694938,
DURATION: 0.28628 seconds,
MODE: Query all rows,
STATUS: success,
COMMAND: select * from psproj.tarefas
[07/17/2017 18:59:48] INFO [OmniDB_app.views.login:37] User "admin" logged out.
[07/17/2017 18:59:58] INFO [OmniDB_app.views.login:103] User "admin" logged in.
[07/17/2017 19:00:03] INFO [OmniDB_app.views.login:37] User "admin" logged out.
[07/17/2017 20:57:16] INFO [OmniDB_app.views.login:103] User "admin" logged in.
[07/17/2017 21:02:07] ERROR [django.request:135] Internal Server Error: /get_tables_postgresql/
Traceback (most recent call last):
  File "/home/israel/.local/lib/python3.5/site-packages/django/core/handlers/exception.py", line 41, in inner
    response = get_response(request)
  File "/home/israel/.local/lib/python3.5/site-packages/django/core/handlers/base.py", line 187, in _get_response
    response = self.process_exception_by_middleware(e, request)
  File "/home/israel/.local/lib/python3.5/site-packages/django/core/handlers/base.py", line 185, in _get_response
    response = wrapped_callback(request, *callback_args, **callback_kwargs)
  File "/home/israel/Repositórios/OmniDB/OmniDB/OmniDB_app/views/tree_postgresql.py", line 84, in get_tables
    v_database = v_session.v_databases[v_database_index]['database']
IndexError: list index out of range
[07/17/2017 21:02:07] ERROR [django.server:124] "POST /get_tables_postgresql/ HTTP/1.1" 500 18363
[07/17/2017 21:02:56] INFO [OmniDB_app.QueryServer:234] *** SQL Command ***
USER: admin,
START: 2017-07-17 21:02:56.501205,
END: 2017-07-17 21:02:56.531970,
DURATION: 0.030765 seconds,
MODE: Query 10 rows,
STATUS: success,
COMMAND: -- Querying Data
select t.*
from psproj.anexos t
[07/17/2017 21:02:59] INFO [OmniDB_app.QueryServer:234] *** SQL Command ***
USER: admin,
START: 2017-07-17 21:02:59.299089,
END: 2017-07-17 21:02:59.327420,
DURATION: 0.028331 seconds,
MODE: Query 10 rows,
STATUS: success,
COMMAND: -- Querying Data
select t.*
from psproj.anexos t
[07/17/2017 21:13:08] INFO [OmniDB_app.QueryServer:234] *** SQL Command ***
USER: admin,
START: 2017-07-17 21:13:08.076010,
END: 2017-07-17 21:13:08.106742,
DURATION: 0.030732 seconds,
MODE: Query 10 rows,
STATUS: success,
COMMAND: -- Querying Data
select t.*
from public.omnidb_mig_commands t
[07/17/2017 21:13:46] INFO [OmniDB_app.QueryServer:234] *** SQL Command ***
USER: admin,
START: 2017-07-17 21:13:46.362163,
END: 2017-07-17 21:13:46.390127,
DURATION: 0.027964 seconds,
MODE: Query 10 rows,
STATUS: success,
COMMAND: -- Counting Records
select count(*) as count
from public.omnidb_mig_commands t
[07/17/2017 21:19:51] INFO [OmniDB_app.QueryServer:234] *** SQL Command ***
USER: admin,
START: 2017-07-17 21:19:51.470710,
END: 2017-07-17 21:19:51.506386,
DURATION: 0.035676 seconds,
MODE: Query 10 rows,
STATUS: success,
COMMAND: select * from psproj.tarefas
[07/17/2017 21:25:49] INFO [OmniDB_app.QueryServer:234] *** SQL Command ***
USER: admin,
START: 2017-07-17 21:25:49.229766,
END: 2017-07-17 21:25:49.263740,
DURATION: 0.033974 seconds,
MODE: Query 10 rows,
STATUS: success,
COMMAND: select * from psproj.tarefas
[07/17/2017 21:25:59] INFO [OmniDB_app.views.login:37] User "admin" logged out.
[07/17/2017 21:26:02] INFO [OmniDB_app.views.login:103] User "admin" logged in.
[07/17/2017 21:26:09] INFO [OmniDB_app.views.login:37] User "admin" logged out.
